Workbook

Sheet Read Me
A1: Model risk management package — workbook guide
A2: POLICY DEVELOPMENT DRAFT — NOT IN FORCE | Information verified to 25 July 2026
A4: Item | B4: Explanation
A5: Package status | B5: POLICY DEVELOPMENT DRAFT — NOT IN FORCE. This workbook, the draft CPS XXXX and the draft CPG XXXX are policy-development artefacts with no legal effect.
A6: As-of date | B6: 25 July 2026. Source status was checked on this date. Regulatory positions change; re-verify before relying on any status statement.
A7: Purpose | B7: Evidence base, comparator assessment, gap scoring, traceability and red-team audit trail for a proposed cross-industry prudential standard on model risk management.
A8: Scope of the comparison | B8: Eight authorities: APRA, the US OCC and Federal Reserve, the PRA, OSFI, the ECB/SSM, MAS, the BCBS and the FSB.
A9: How to use | B9: Start with Executive Summary, then Scoring Methodology so the numbers can be interpreted. Gap Assessment carries the scores; Areas for Improvement is the prioritised output. Regulatory Crosswalk compares by domain; Requirement Test challenges each drafted requirement authority by authority. Red Team Audit records every correction.
A10: What the scoring measures | B10: How well the CURRENT Australian prudential framework addresses each model risk domain, against the strongest comparator practice. It does not score entity maturity and does not rank the comparator authorities against one another.
A11: Legal caution | B11: An overseas instrument is not binding in Australia whatever its status at home. Several of the most influential model risk instruments — including the US interagency guidance and PRA SS1/23 — are supervisory guidance rather than law even in their home jurisdiction. The Legal Status Matrix records this for each source.
A12: Provenance labels | B12: Extracted = close reflection of an explicit source requirement. Extracted + inferred = faithful synthesis across sources. Inferred = reasoned construction. Policy choice = proposed by the drafter, not directly mandated by any comparator. 'Policy choice' does not mean unsupported.
A13: Verification labels | B13: Verified — primary source: confirmed from the issuing authority's own document. Verified — secondary source: confirmed only from a reputable third party. Unverified: could not be confirmed and is not relied upon for any statement of requirement.
A14: Editable cells | B14: Blue text on a yellow fill marks an input you may change — domain weights and the priority band thresholds on Scoring Methodology. Everything downstream recalculates.
A15: Reproducibility | B15: Every artefact in this package is generated by the scripts in the build/ directory of the source repository, and can be regenerated or re-verified through the accompanying MCP server.

Sheet Executive Summary
A1: Executive summary
A2: POLICY DEVELOPMENT DRAFT — NOT IN FORCE | Counts are formulas linked to the detailed sheets.
A4: Metric | B4: Value | C4: Interpretation
A5: Draft mandatory requirements | B5: =COUNTA('Requirements Register'!A5:A200) -> 45 | C5: Bold mandatory paragraphs in draft CPS XXXX.
A6: Requirements that are policy choices | B6: =COUNTIF('Requirements Register'!I5:I200,"Yes") -> 5 | C6: Proposed by the drafter rather than mandated by a comparator. Require consultation and cost-benefit testing.
A7: Requirements flagged for legal settlement | B7: =COUNTIF('Requirements Register'!J5:J200,"Yes") -> 7 | C7: Carry an express legal-drafting reservation.
A8: Guidance paragraphs in draft CPG XXXX | B8: =COUNTA(Traceability!A5:A200) -> 146 | C8: Every requirement has at least one supporting guidance paragraph.
A9: Domains assessed | B9: =COUNTA('Gap Assessment'!A5:A39) -> 35 | C9: Model risk domains scored against the strongest comparator.
A10: Mean current Australian score (0-5) | B10: =ROUND(AVERAGE('Gap Assessment'!H5:H39),2) -> 2.28 | C10: Weighted mean across all domains of the framework as it stands today.
A11: Mean expected score after CPS XXXX | B11: =ROUND(AVERAGE('Gap Assessment'!L5:L39),2) -> 4.41 | C11: Expected position once CPS XXXX and CPG XXXX are in force.
A12: Critical priority gaps | B12: =COUNTIF('Gap Assessment'!K5:K39,"Critical") -> 4 | C12: Gaps that could permit material unmanaged model risk.
A13: High priority gaps | B13: =COUNTIF('Gap Assessment'!K5:K39,"High") -> 17 | C13: Significant divergence from the strongest comparator.
A14: Red-team corrections recorded | B14: =COUNTA('Red Team Audit'!A5:A200) -> 66 | C14: Challenges and corrections preserved with evidence.
A15: High-severity red-team items | B15: =COUNTIF('Red Team Audit'!G5:G200,"High") -> 39 | C15: Corrections of greatest legal or factual significance.
A16: Official sources registered | B16: =COUNTA('Source Register'!A5:A200) -> 50 | C16: Sources with an official URL and a recorded check result.
A17: Sources verified from primary text | B17: =COUNTIF('Source Register'!I5:I200,"Verified — primary source") -> 43 | C17: Confirmed by fetching the issuing authority's own document.
A18: Sources not independently confirmed | B18: =COUNTIF('Source Register'!I5:I200,"Unverified — not independently confirmed") -> 0 | C18: Not relied upon for any statement of requirement.
A20: Principal conclusions
A21: 1 | B21: Australia has strong model requirements for regulatory capital models and a strong actuarial control cycle, and very little else. Outside those regimes a model driving material decisions may never be independently validated.
A22: 2 | B22: The largest gaps are conceptual rather than technical: no cross-industry definition of a model, no inventory obligation, no concept of effective challenge, and no requirement to consider model risk in aggregate.
A23: 3 | B23: Model misuse — applying a sound model outside its approved purpose — is one of the two recognised sources of model risk and is almost entirely unaddressed in the current framework.
A24: 4 | B24: The US interagency guidance remains the source of most of the discipline's architecture, but it is supervisory guidance, not law, and should be cited as such.
A25: 5 | B25: Bringing AI models within the model risk framework, with an express boundary rule against the separate AI instrument, avoids the risk of a system being governed as one and not the other.
A26: 6 | B26: Notification should cross-reference the existing CPS 230 and CPS 234 architecture. A model-specific deadline was considered and rejected as conflicting.

Sheet Scoring Methodology
A1: Scoring methodology
A2: POLICY DEVELOPMENT DRAFT — NOT IN FORCE | Weights and thresholds below are inputs. Change them and the Gap Assessment recalculates.
A4: Element | B4: Definition
A5: What is scored | B5: The CURRENT Australian prudential framework, as it stands before CPS 240, in each model risk domain. Not entity maturity, and not a ranking of the comparator authorities against one another.
A6: Against what | B6: The strongest comparator practice in that domain, identified by authority. Where no comparator addresses a domain at all — superannuation models — the benchmark is recorded as absent and the domain is assessed against the standard's own cross-industry objective instead.
A7: Scale | B7: 0 to 5 on each of four dimensions. The domain score is the unweighted mean of the four dimensions, so no single dimension can carry a domain.
A8: Why four dimensions | B8: A domain can be addressed but vaguely, or precisely but only in guidance. Splitting coverage from specificity from enforceability prevents a general obligation in a binding standard from scoring as though it were a specific one.
A10: The four dimensions
A11: Coverage | B11: Is the domain addressed at all in the framework?
A12: Specificity | B12: Is the expectation precise enough to be evidenced and supervised?
A13: Enforceability | B13: For Australia: binding instrument, guidance, or nothing? Comparator benchmarks are not scored on this dimension, since most of the strongest model risk expectations internationally sit in supervisory guidance rather than law.
A14: Alignment | B14: Does it match the strongest comparator practice?
A16: The 0–5 rubric
A17: Score | B17: Meaning
A18: 5 — Leading practice | B18: Addressed comprehensively and specifically enough that compliance can be evidenced and supervised. Matches or exceeds the strongest comparator. Scored on the quality and specificity of the expectation, irrespective of the instrument type carrying it — enforceability is scored separately.
A19: 4 — Strong | B19: Addressed with clear expectations. Minor gaps in specificity or in coverage of edge cases relative to the strongest comparator.
A20: 3 — Adequate | B20: Addressed, but at a level of generality that leaves material discretion, or in a way that would be difficult to supervise consistently.
A21: 2 — Partial | B21: Addressed indirectly or by implication, through a general obligation not specific to model risk. Compliance would be difficult to evidence or to supervise consistently.
A22: 1 — Incidental | B22: Touched on only for a narrow class of models or entities, or mentioned without expectation.
A23: 0 — Absent | B23: Not addressed in the framework at all.
A25: Derived measures
A26: Domain score | B26: Mean of the four dimension scores for Australia. Column H of Gap Assessment.
A27: Benchmark | B27: The strongest comparator score in that domain, with the authority named. Column I of Gap Assessment.
A28: Gap | B28: MAX(0, Benchmark − Domain score). Negative gaps are floored at zero: where Australia already matches or exceeds the benchmark there is nothing to close.
A29: Weighted gap | B29: Gap × domain weight. This is what drives the priority band.
A30: Expected score after CPS XXXX | B30: Assessed position once the draft standard and guide are in force, on the same 0–5 scale. The difference from the current score is the value the instrument is expected to add.
A32: Priority band thresholds — editable
A33: Band | B33: Weighted gap at or above | C33: Meaning
A34: Critical | B34: 4.5 | C34: Framework gap of a kind that could permit material unmanaged model risk. Address before or at consultation.
A35: High | B35: 3 | C35: Significant divergence from the strongest comparator with a clear prudential rationale for closing it.
A36: Medium | B36: 1.5 | C36: Meaningful but not urgent. Suitable for the practice guide or for supervisory attention rather than a new obligation.
A37: Low | B37: 0 | C37: Broadly comparable to international practice. No action proposed.
A39: Domain weights — editable
A40: Domain | B40: Weight | C40: Why this weight
A41: Definition of a model and of model risk | B41: 1.5 | C41: Direct effect on capital, provisions, reported figures or member outcomes.
A42: Enterprise-wide scope and retained accountability | B42: 1.25 | C42: Material to the integrity of the framework as a whole.
A43: Model inventory | B43: 1.25 | C43: Material to the integrity of the framework as a whole.
A44: Model risk tiering and proportionality | B44: 1.25 | C44: Material to the integrity of the framework as a whole.
A45: Board oversight of model risk | B45: 1.5 | C45: Direct effect on capital, provisions, reported figures or member outcomes.
A46: Senior accountability for the framework | B46: 1.25 | C46: Material to the integrity of the framework as a whole.
...

Sheet Gap Assessment
A1: Gap assessment — current Australian framework against strongest comparator
A2: POLICY DEVELOPMENT DRAFT — NOT IN FORCE | Scores 0–5 per the Scoring Methodology sheet. Every score cell carries a comment giving the reasoning.
A4: Domain | B4: Coverage | C4: Specificity | D4: Enforceability | E4: Alignment | F4: Weight | G4: Benchmark authority | H4: AU score now | I4: Benchmark | J4: Weighted gap | K4: Priority | L4: Expected after CPS XXXX | M4: Uplift | N4: CPS XXXX requirements | O4: Source IDs
A5: Definition of a model and of model risk | B5: 1 | C5: 1 | D5: 2 | E5: 1 | F5: ='Scoring Methodology'!$B$41 -> 1.5 | G5: PRA / OSFI | H5: =ROUND(AVERAGE(B5:E5),2) -> 1.25 | I5: 5 | J5: =ROUND(MAX(0,I5-H5)*F5,2) -> 5.63 | K5: =IF(J5>='Scoring Methodology'!$B$34,"Critical",IF(J5>='Scoring Methodology'!$B$35,"High",IF(J5>='Scoring Methodology'!$B$36,"Medium","Low"))) -> Critical | L5: 4.5 | M5: =ROUND(L5-H5,2) -> 3.25 | N5: M02, M03 | O5: US-MRM-2026, PRA-SS1-23, OSFI-E23
A6: Enterprise-wide scope and retained accountability | B6: 2 | C6: 2 | D6: 3 | E6: 2 | F6: ='Scoring Methodology'!$B$42 -> 1.25 | G6: OSFI | H6: =ROUND(AVERAGE(B6:E6),2) -> 2.25 | I6: 5 | J6: =ROUND(MAX(0,I6-H6)*F6,2) -> 3.44 | K6: =IF(J6>='Scoring Methodology'!$B$34,"Critical",IF(J6>='Scoring Methodology'!$B$35,"High",IF(J6>='Scoring Methodology'!$B$36,"Medium","Low"))) -> High | L6: 4.5 | M6: =ROUND(L6-H6,2) -> 2.25 | N6: M01 | O6: OSFI-E23, US-MRM-2026, APRA-CPS220
A7: Model inventory | B7: 1 | C7: 1 | D7: 2 | E7: 1 | F7: ='Scoring Methodology'!$B$43 -> 1.25 | G7: PRA | H7: =ROUND(AVERAGE(B7:E7),2) -> 1.25 | I7: 5 | J7: =ROUND(MAX(0,I7-H7)*F7,2) -> 4.69 | K7: =IF(J7>='Scoring Methodology'!$B$34,"Critical",IF(J7>='Scoring Methodology'!$B$35,"High",IF(J7>='Scoring Methodology'!$B$36,"Medium","Low"))) -> Critical | L7: 4.5 | M7: =ROUND(L7-H7,2) -> 3.25 | N7: M14 | O7: PRA-SS1-23, OSFI-E23, US-MRM-2026
A8: Model risk tiering and proportionality | B8: 2 | C8: 1 | D8: 3 | E8: 2 | F8: ='Scoring Methodology'!$B$44 -> 1.25 | G8: PRA | H8: =ROUND(AVERAGE(B8:E8),2) -> 2 | I8: 5 | J8: =ROUND(MAX(0,I8-H8)*F8,2) -> 3.75 | K8: =IF(J8>='Scoring Methodology'!$B$34,"Critical",IF(J8>='Scoring Methodology'!$B$35,"High",IF(J8>='Scoring Methodology'!$B$36,"Medium","Low"))) -> High | L8: 4.5 | M8: =ROUND(L8-H8,2) -> 2.5 | N8: M04, M05, M15, M16 | O8: PRA-SS1-23, OSFI-E23
A9: Board oversight of model risk | B9: 2 | C9: 2 | D9: 4 | E9: 2 | F9: ='Scoring Methodology'!$B$45 -> 1.5 | G9: PRA | H9: =ROUND(AVERAGE(B9:E9),2) -> 2.5 | I9: 5 | J9: =ROUND(MAX(0,I9-H9)*F9,2) -> 3.75 | K9: =IF(J9>='Scoring Methodology'!$B$34,"Critical",IF(J9>='Scoring Methodology'!$B$35,"High",IF(J9>='Scoring Methodology'!$B$36,"Medium","Low"))) -> High | L9: 4.5 | M9: =ROUND(L9-H9,2) -> 2 | N9: M06, M13 | O9: PRA-SS1-23, OSFI-E23, APRA-CPS220
A10: Senior accountability for the framework | B10: 2 | C10: 2 | D10: 4 | E10: 2 | F10: ='Scoring Methodology'!$B$46 -> 1.25 | G10: PRA | H10: =ROUND(AVERAGE(B10:E10),2) -> 2.5 | I10: 5 | J10: =ROUND(MAX(0,I10-H10)*F10,2) -> 3.13 | K10: =IF(J10>='Scoring Methodology'!$B$34,"Critical",IF(J10>='Scoring Methodology'!$B$35,"High",IF(J10>='Scoring Methodology'!$B$36,"Medium","Low"))) -> High | L10: 4.5 | M10: =ROUND(L10-H10,2) -> 2 | N10: M07, M08 | O10: PRA-SS1-23, OSFI-E23
A11: MRM framework, policies and capability | B11: 2 | C11: 1 | D11: 3 | E11: 2 | F11: ='Scoring Methodology'!$B$47 -> 1.25 | G11: PRA / OSFI | H11: =ROUND(AVERAGE(B11:E11),2) -> 2 | I11: 5 | J11: =ROUND(MAX(0,I11-H11)*F11,2) -> 3.75 | K11: =IF(J11>='Scoring Methodology'!$B$34,"Critical",IF(J11>='Scoring Methodology'!$B$35,"High",IF(J11>='Scoring Methodology'!$B$36,"Medium","Low"))) -> High | L11: 4.5 | M11: =ROUND(L11-H11,2) -> 2.5 | N11: M09, M10, M12 | O11: PRA-SS1-23, OSFI-E23, APRA-CPS220
A12: Model risk appetite | B12: 2 | C12: 1 | D12: 3 | E12: 2 | F12: ='Scoring Methodology'!$B$48 -> 1 | G12: PRA | H12: =ROUND(AVERAGE(B12:E12),2) -> 2 | I12: 4 | J12: =ROUND(MAX(0,I12-H12)*F12,2) -> 2 | K12: =IF(J12>='Scoring Methodology'!$B$34,"Critical",IF(J12>='Scoring Methodology'!$B$35,"High",IF(J12>='Scoring Methodology'!$B$36,"Medium","Low"))) -> Medium | L12: 4 | M12: =ROUND(L12-H12,2) -> 2 | N12: M11 | O12: PRA-SS1-23, OSFI-E23, APRA-CPS220
A13: Development and conceptual soundness | B13: 2 | C13: 2 | D13: 4 | E13: 2 | F13: ='Scoring Methodology'!$B$49 -> 1.25 | G13: US interagency (OCC/FRB/FDIC) | H13: =ROUND(AVERAGE(B13:E13),2) -> 2.5 | I13: 5 | J13: =ROUND(MAX(0,I13-H13)*F13,2) -> 3.13 | K13: =IF(J13>='Scoring Methodology'!$B$34,"Critical",IF(J13>='Scoring Methodology'!$B$35,"High",IF(J13>='Scoring Methodology'!$B$36,"Medium","Low"))) -> High | L13: 4.5 | M13: =ROUND(L13-H13,2) -> 2 | N13: M17 | O13: US-MRM-2026, PRA-SS1-23, ECB-GIM
A14: Data quality, provenance and appropriateness | B14: 3 | C14: 2 | D14: 3 | E14: 3 | F14: ='Scoring Methodology'!$B$50 -> 1.25 | G14: BCBS / ECB | H14: =ROUND(AVERAGE(B14:E14),2) -> 2.75 | I14: 5 | J14: =ROUND(MAX(0,I14-H14)*F14,2) -> 2.81 | K14: =IF(J14>='Scoring Methodology'!$B$34,"Critical",IF(J14>='Scoring Methodology'!$B$35,"High",IF(J14>='Scoring Methodology'!$B$36,"Medium","Low"))) -> Medium | L14: 4.5 | M14: =ROUND(L14-H14,2) -> 1.75 | N14: M18 | O14: BCBS-239, ECB-RDARR, APRA-CPG235, OSFI-E23
A15: Documentation and reproducibility | B15: 2 | C15: 2 | D15: 3 | E15: 2 | F15: ='Scoring Methodology'!$B$51 -> 1 | G15: ECB / PRA | H15: =ROUND(AVERAGE(B15:E15),2) -> 2.25 | I15: 5 | J15: =ROUND(MAX(0,I15-H15)*F15,2) -> 2.75 | K15: =IF(J15>='Scoring Methodology'!$B$34,"Critical",IF(J15>='Scoring Methodology'!$B$35,"High",IF(J15>='Scoring Methodology'!$B$36,"Medium","Low"))) -> Medium | L15: 4.5 | M15: =ROUND(L15-H15,2) -> 2.25 | N15: M19 | O15: US-MRM-2026, PRA-SS1-23, ECB-GIM
A16: Pre-implementation testing | B16: 2 | C16: 1 | D16: 3 | E16: 2 | F16: ='Scoring Methodology'!$B$52 -> 1.25 | G16: PRA / ECB | H16: =ROUND(AVERAGE(B16:E16),2) -> 2 | I16: 5 | J16: =ROUND(MAX(0,I16-H16)*F16,2) -> 3.75 | K16: =IF(J16>='Scoring Methodology'!$B$34,"Critical",IF(J16>='Scoring Methodology'!$B$35,"High",IF(J16>='Scoring Methodology'!$B$36,"Medium","Low"))) -> High | L16: 4.5 | M16: =ROUND(L16-H16,2) -> 2.5 | N16: M20 | O16: US-MRM-2026, PRA-SS1-23, OSFI-E23
A17: Independent validation | B17: 2 | C17: 2 | D17: 4 | E17: 2 | F17: ='Scoring Methodology'!$B$53 -> 1.5 | G17: PRA | H17: =ROUND(AVERAGE(B17:E17),2) -> 2.5 | I17: 5 | J17: =ROUND(MAX(0,I17-H17)*F17,2) -> 3.75 | K17: =IF(J17>='Scoring Methodology'!$B$34,"Critical",IF(J17>='Scoring Methodology'!$B$35,"High",IF(J17>='Scoring Methodology'!$B$36,"Medium","Low"))) -> High | L17: 5 | M17: =ROUND(L17-H17,2) -> 2.5 | N17: M21, M22, M25 | O17: PRA-SS1-23, US-MRM-2026, OSFI-E23, ECB-GIM
A18: Effective challenge | B18: 1 | C18: 1 | D18: 2 | E18: 1 | F18: ='Scoring Methodology'!$B$54 -> 1.5 | G18: US interagency (OCC/FRB/FDIC) | H18: =ROUND(AVERAGE(B18:E18),2) -> 1.25 | I18: 5 | J18: =ROUND(MAX(0,I18-H18)*F18,2) -> 5.63 | K18: =IF(J18>='Scoring Methodology'!$B$34,"Critical",IF(J18>='Scoring Methodology'!$B$35,"High",IF(J18>='Scoring Methodology'!$B$36,"Medium","Low"))) -> Critical | L18: 4.5 | M18: =ROUND(L18-H18,2) -> 3.25 | N18: M23 | O18: US-MRM-2026, PRA-SS1-23
A19: Approval and conditions of use | B19: 2 | C19: 2 | D19: 4 | E19: 2 | F19: ='Scoring Methodology'!$B$55 -> 1 | G19: ECB | H19: =ROUND(AVERAGE(B19:E19),2) -> 2.5 | I19: 5 | J19: =ROUND(MAX(0,I19-H19)*F19,2) -> 2.5 | K19: =IF(J19>='Scoring Methodology'!$B$34,"Critical",IF(J19>='Scoring Methodology'!$B$35,"High",IF(J19>='Scoring Methodology'!$B$36,"Medium","Low"))) -> Medium | L19: 4.5 | M19: =ROUND(L19-H19,2) -> 2 | N19: M24 | O19: ECB-GIM, OSFI-E23, US-MRM-2026
A20: Implementation controls | B20: 1 | C20: 1 | D20: 3 | E20: 1 | F20: ='Scoring Methodology'!$B$56 -> 1 | G20: ECB | H20: =ROUND(AVERAGE(B20:E20),2) -> 1.5 | I20: 5 | J20: =ROUND(MAX(0,I20-H20)*F20,2) -> 3.5 | K20: =IF(J20>='Scoring Methodology'!$B$34,"Critical",IF(J20>='Scoring Methodology'!$B$35,"High",IF(J20>='Scoring Methodology'!$B$36,"Medium","Low"))) -> High | L20: 4 | M20: =ROUND(L20-H20,2) -> 2.5 | N20: M25 | O20: ECB-GIM, US-MRM-2026, OSFI-E23
A21: Change management and re-approval | B21: 2 | C21: 2 | D21: 4 | E21: 2 | F21: ='Scoring Methodology'!$B$57 -> 1.25 | G21: ECB | H21: =ROUND(AVERAGE(B21:E21),2) -> 2.5 | I21: 5 | J21: =ROUND(MAX(0,I21-H21)*F21,2) -> 3.13 | K21: =IF(J21>='Scoring Methodology'!$B$34,"Critical",IF(J21>='Scoring Methodology'!$B$35,"High",IF(J21>='Scoring Methodology'!$B$36,"Medium","Low"))) -> High | L21: 4.5 | M21: =ROUND(L21-H21,2) -> 2 | N21: M26 | O21: ECB-GIM, OSFI-E23, PRA-SS1-23
A22: Model use and misuse | B22: 1 | C22: 1 | D22: 3 | E22: 1 | F22: ='Scoring Methodology'!$B$58 -> 1.25 | G22: US interagency / ECB | H22: =ROUND(AVERAGE(B22:E22),2) -> 1.5 | I22: 5 | J22: =ROUND(MAX(0,I22-H22)*F22,2) -> 4.38 | K22: =IF(J22>='Scoring Methodology'!$B$34,"Critical",IF(J22>='Scoring Methodology'!$B$35,"High",IF(J22>='Scoring Methodology'!$B$36,"Medium","Low"))) -> High | L22: 4.5 | M22: =ROUND(L22-H22,2) -> 3 | N22: M27 | O22: US-MRM-2026, ECB-GIM, PRA-SS1-23
A23: Overlays, adjustments and expert judgement | B23: 2 | C23: 1 | D23: 3 | E23: 2 | F23: ='Scoring Methodology'!$B$59 -> 1.25 | G23: PRA | H23: =ROUND(AVERAGE(B23:E23),2) -> 2 | I23: 5 | J23: =ROUND(MAX(0,I23-H23)*F23,2) -> 3.75 | K23: =IF(J23>='Scoring Methodology'!$B$34,"Critical",IF(J23>='Scoring Methodology'!$B$35,"High",IF(J23>='Scoring Methodology'!$B$36,"Medium","Low"))) -> High | L23: 4.5 | M23: =ROUND(L23-H23,2) -> 2.5 | N23: M28 | O23: PRA-SS1-23, ECB-GIM
A24: Ongoing monitoring and drift | B24: 2 | C24: 2 | D24: 3 | E24: 2 | F24: ='Scoring Methodology'!$B$60 -> 1.25 | G24: US interagency / OSFI | H24: =ROUND(AVERAGE(B24:E24),2) -> 2.25 | I24: 5 | J24: =ROUND(MAX(0,I24-H24)*F24,2) -> 3.44 | K24: =IF(J24>='Scoring Methodology'!$B$34,"Critical",IF(J24>='Scoring Methodology'!$B$35,"High",IF(J24>='Scoring Methodology'!$B$36,"Medium","Low"))) -> High | L24: 4.5 | M24: =ROUND(L24-H24,2) -> 2.25 | N24: M29 | O24: US-MRM-2026, OSFI-E23, PRA-SS1-23
A25: Limitations, mitigants and remediation | B25: 2 | C25: 1 | D25: 3 | E25: 2 | F25: ='Scoring Methodology'!$B$61 -> 1 | G25: PRA | H25: =ROUND(AVERAGE(B25:E25),2) -> 2 | I25: 5 | J25: =ROUND(MAX(0,I25-H25)*F25,2) -> 3 | K25: =IF(J25>='Scoring Methodology'!$B$34,"Critical",IF(J25>='Scoring Methodology'!$B$35,"High",IF(J25>='Scoring Methodology'!$B$36,"Medium","Low"))) -> High | L25: 4.5 | M25: =ROUND(L25-H25,2) -> 2.5 | N25: M30 | O25: PRA-SS1-23, US-MRM-2026
A26: Decommissioning and retirement | B26: 1 | C26: 1 | D26: 2 | E26: 1 | F26: ='Scoring Methodology'!$B$62 -> 0.75 | G26: OSFI | H26: =ROUND(AVERAGE(B26:E26),2) -> 1.25 | I26: 4 | J26: =ROUND(MAX(0,I26-H26)*F26,2) -> 2.06 | K26: =IF(J26>='Scoring Methodology'!$B$34,"Critical",IF(J26>='Scoring Methodology'!$B$35,"High",IF(J26>='Scoring Methodology'!$B$36,"Medium","Low"))) -> Medium | L26: 4 | M26: =ROUND(L26-H26,2) -> 2.75 | N26: M31 | O26: OSFI-E23, APRA-CPS230
A27: Third-party and vendor models | B27: 2 | C27: 2 | D27: 4 | E27: 2 | F27: ='Scoring Methodology'!$B$63 -> 1.25 | G27: US interagency / PRA | H27: =ROUND(AVERAGE(B27:E27),2) -> 2.5 | I27: 5 | J27: =ROUND(MAX(0,I27-H27)*F27,2) -> 3.13 | K27: =IF(J27>='Scoring Methodology'!$B$34,"Critical",IF(J27>='Scoring Methodology'!$B$35,"High",IF(J27>='Scoring Methodology'!$B$36,"Medium","Low"))) -> High | L27: 4.5 | M27: =ROUND(L27-H27,2) -> 2 | N27: M32, M33 | O27: US-MRM-2026, PRA-SS1-23, BCBS-TPRM, APRA-CPS230
A28: Concentration and substitutability | B28: 2 | C28: 1 | D28: 3 | E28: 2 | F28: ='Scoring Methodology'!$B$64 -> 1 | G28: FSB / BCBS | H28: =ROUND(AVERAGE(B28:E28),2) -> 2 | I28: 4 | J28: =ROUND(MAX(0,I28-H28)*F28,2) -> 2 | K28: =IF(J28>='Scoring Methodology'!$B$34,"Critical",IF(J28>='Scoring Methodology'!$B$35,"High",IF(J28>='Scoring Methodology'!$B$36,"Medium","Low"))) -> Medium | L28: 4 | M28: =ROUND(L28-H28,2) -> 2 | N28: M33 | O28: FSB-AI-2024, BCBS-TPRM, APRA-CPS230
A29: AI and machine learning models | B29: 2 | C29: 2 | D29: 3 | E29: 2 | F29: ='Scoring Methodology'!$B$65 -> 1.25 | G29: OSFI | H29: =ROUND(AVERAGE(B29:E29),2) -> 2.25 | I29: 5 | J29: =ROUND(MAX(0,I29-H29)*F29,2) -> 3.44 | K29: =IF(J29>='Scoring Methodology'!$B$34,"Critical",IF(J29>='Scoring Methodology'!$B$35,"High",IF(J29>='Scoring Methodology'!$B$36,"Medium","Low"))) -> High | L29: 4.5 | M29: =ROUND(L29-H29,2) -> 2.25 | N29: M34, M35 | O29: OSFI-E23, MAS-AIMRM-2024, BCBS-DIGI, FSB-AI-2024
A30: Regulatory capital and internal models | B30: 4 | C30: 4 | D30: 5 | E30: 4 | F30: ='Scoring Methodology'!$B$66 -> 1.5 | G30: ECB | H30: =ROUND(AVERAGE(B30:E30),2) -> 4.25 | I30: 5 | J30: =ROUND(MAX(0,I30-H30)*F30,2) -> 1.13 | K30: =IF(J30>='Scoring Methodology'!$B$34,"Critical",IF(J30>='Scoring Methodology'!$B$35,"High",IF(J30>='Scoring Methodology'!$B$36,"Medium","Low"))) -> Low | L30: 4.75 | M30: =ROUND(L30-H30,2) -> 0.5 | N30: M36 | O30: APRA-APS113, ECB-GIM, ECB-CRR, PRA-SS1-23
A31: Valuation and financial reporting models | B31: 2 | C31: 2 | D31: 3 | E31: 2 | F31: ='Scoring Methodology'!$B$67 -> 1.25 | G31: BCBS | H31: =ROUND(AVERAGE(B31:E31),2) -> 2.25 | I31: 4 | J31: =ROUND(MAX(0,I31-H31)*F31,2) -> 2.19 | K31: =IF(J31>='Scoring Methodology'!$B$34,"Critical",IF(J31>='Scoring Methodology'!$B$35,"High",IF(J31>='Scoring Methodology'!$B$36,"Medium","Low"))) -> Medium | L31: 4 | M31: =ROUND(L31-H31,2) -> 1.75 | N31: M37 | O31: BCBS-FVP, ECB-GIM
A32: Expected credit loss and provisioning models | B32: 4 | C32: 4 | D32: 5 | E32: 4 | F32: ='Scoring Methodology'!$B$68 -> 1.5 | G32: BCBS | H32: =ROUND(AVERAGE(B32:E32),2) -> 4.25 | I32: 5 | J32: =ROUND(MAX(0,I32-H32)*F32,2) -> 1.13 | K32: =IF(J32>='Scoring Methodology'!$B$34,"Critical",IF(J32>='Scoring Methodology'!$B$35,"High",IF(J32>='Scoring Methodology'!$B$36,"Medium","Low"))) -> Low | L32: 4.75 | M32: =ROUND(L32-H32,2) -> 0.5 | N32: M38 | O32: APRA-APS220, APRA-APG220, BCBS-ECL-2015, APRA-PROV-2023, AASB-9, APRA-APS310
A33: Actuarial and insurance models | B33: 3 | C33: 3 | D33: 4 | E33: 3 | F33: ='Scoring Methodology'!$B$69 -> 1.25 | G33: OSFI | H33: =ROUND(AVERAGE(B33:E33),2) -> 3.25 | I33: 4 | J33: =ROUND(MAX(0,I33-H33)*F33,2) -> 0.94 | K33: =IF(J33>='Scoring Methodology'!$B$34,"Critical",IF(J33>='Scoring Methodology'!$B$35,"High",IF(J33>='Scoring Methodology'!$B$36,"Medium","Low"))) -> Low | L33: 4.5 | M33: =ROUND(L33-H33,2) -> 1.25 | N33: M39 | O33: APRA-CPS320, OSFI-E23
A34: Superannuation models | B34: 1 | C34: 1 | D34: 3 | E34: 1 | F34: ='Scoring Methodology'!$B$70 -> 1.25 | G34: No comparator — assessed against the standard's own cross-industry objective | H34: =ROUND(AVERAGE(B34:E34),2) -> 1.5 | I34: 5 | J34: =ROUND(MAX(0,I34-H34)*F34,2) -> 4.38 | K34: =IF(J34>='Scoring Methodology'!$B$34,"Critical",IF(J34>='Scoring Methodology'!$B$35,"High",IF(J34>='Scoring Methodology'!$B$36,"Medium","Low"))) -> High | L34: 4 | M34: =ROUND(L34-H34,2) -> 2.5 | N34: M40 | O34: APRA-SPS530, APRA-SPS515
A35: Stress testing and scenario models | B35: 3 | C35: 2 | D35: 4 | E35: 3 | F35: ='Scoring Methodology'!$B$71 -> 1 | G35: PRA / BCBS | H35: =ROUND(AVERAGE(B35:E35),2) -> 3 | I35: 5 | J35: =ROUND(MAX(0,I35-H35)*F35,2) -> 2 | K35: =IF(J35>='Scoring Methodology'!$B$34,"Critical",IF(J35>='Scoring Methodology'!$B$35,"High",IF(J35>='Scoring Methodology'!$B$36,"Medium","Low"))) -> Medium | L35: 4.5 | M35: =ROUND(L35-H35,2) -> 1.5 | N35: M41 | O35: BCBS-STRESS, PRA-SS3-18, APRA-CPS220
A36: Aggregate model risk and capital | B36: 1 | C36: 1 | D36: 2 | E36: 1 | F36: ='Scoring Methodology'!$B$72 -> 1.25 | G36: PRA | H36: =ROUND(AVERAGE(B36:E36),2) -> 1.25 | I36: 5 | J36: =ROUND(MAX(0,I36-H36)*F36,2) -> 4.69 | K36: =IF(J36>='Scoring Methodology'!$B$34,"Critical",IF(J36>='Scoring Methodology'!$B$35,"High",IF(J36>='Scoring Methodology'!$B$36,"Medium","Low"))) -> Critical | L36: 4 | M36: =ROUND(L36-H36,2) -> 2.75 | N36: M42 | O36: PRA-SS1-23, ECB-GIM, US-MRM-2026, APRA-SPS114
A37: Records and reconstructability | B37: 2 | C37: 2 | D37: 4 | E37: 2 | F37: ='Scoring Methodology'!$B$73 -> 1 | G37: ECB | H37: =ROUND(AVERAGE(B37:E37),2) -> 2.5 | I37: 4 | J37: =ROUND(MAX(0,I37-H37)*F37,2) -> 1.5 | K37: =IF(J37>='Scoring Methodology'!$B$34,"Critical",IF(J37>='Scoring Methodology'!$B$35,"High",IF(J37>='Scoring Methodology'!$B$36,"Medium","Low"))) -> Medium | L37: 4 | M37: =ROUND(L37-H37,2) -> 1.5 | N37: M43 | O37: ECB-GIM, US-MRM-2026, APRA-CPS220
A38: Independent assurance and internal audit | B38: 3 | C38: 2 | D38: 4 | E38: 3 | F38: ='Scoring Methodology'!$B$74 -> 1.25 | G38: PRA | H38: =ROUND(AVERAGE(B38:E38),2) -> 3 | I38: 5 | J38: =ROUND(MAX(0,I38-H38)*F38,2) -> 2.5 | K38: =IF(J38>='Scoring Methodology'!$B$34,"Critical",IF(J38>='Scoring Methodology'!$B$35,"High",IF(J38>='Scoring Methodology'!$B$36,"Medium","Low"))) -> Medium | L38: 4.5 | M38: =ROUND(L38-H38,2) -> 1.5 | N38: M44 | O38: PRA-SS1-23, US-MRM-2026, ECB-GIM, APRA-CPS220
A39: Supervisory engagement and notification | B39: 3 | C39: 3 | D39: 4 | E39: 3 | F39: ='Scoring Methodology'!$B$75 -> 1 | G39: OSFI | H39: =ROUND(AVERAGE(B39:E39),2) -> 3.25 | I39: 4 | J39: =ROUND(MAX(0,I39-H39)*F39,2) -> 0.75 | K39: =IF(J39>='Scoring Methodology'!$B$34,"Critical",IF(J39>='Scoring Methodology'!$B$35,"High",IF(J39>='Scoring Methodology'!$B$36,"Medium","Low"))) -> Low | L39: 4.25 | M39: =ROUND(L39-H39,2) -> 1 | N39: M45 | O39: APRA-CPS230, APRA-CPS234, OSFI-E23
A41: Totals | H41: =ROUND(AVERAGE(H5:H39),2) -> 2.28 | J41: =ROUND(SUM(J5:J39),2) -> 107.5 | L41: =ROUND(AVERAGE(L5:L39),2) -> 4.41 | M41: =ROUND(L41-H41,2) -> 2.13 | N41: Mean AU score, total weighted gap, mean expected score, mean uplift.

Sheet Areas for Improvement
A1: Areas for improvement
A2: POLICY DEVELOPMENT DRAFT — NOT IN FORCE | Ordered by weighted gap. Priority and weighted gap are linked to the Gap Assessment sheet, so re-weighting there re-ranks nothing here automatically — re-sort after changing weights.
A4: Rank | B4: Domain | C4: Priority | D4: Weighted gap | E4: Observed gap | F4: Recommended action | G4: CPS XXXX requirements | H4: Indicative owner | I4: Status
A5: 1 | B5: Definition of a model and of model risk | C5: ='Gap Assessment'!K5 -> Critical | D5: ='Gap Assessment'!J5 -> 5.63 | E5: No APRA instrument defines a model or model risk on a cross-industry basis. Model requirements exist only inside the capital and actuarial standards and apply only to the models those standards cover. | F5: Adopt a broad function-based definition of a model and of model risk on a cross-industry basis, with an express obligation to identify and control quantitative tools falling outside it. Do not follow the April 2026 United States narrowing, which would exclude actuarial and unit pricing calculations. | G5: M02, M03 | H5: Policy | I5: Open — policy development
A6: 2 | B6: Effective challenge | C6: ='Gap Assessment'!K18 -> Critical | D6: ='Gap Assessment'!J18 -> 5.63 | E6: The concept is absent from the Australian framework. Validation can exist on paper without the competence, standing or incentives that make it effective, and nothing currently requires an entity to test whether challenge works. | F6: Require effective challenge expressly, and expect entities to assess whether it is operating through finding closure routes and severity migration. | G6: M23 | H6: Policy + Supervision | I6: Open — policy development
A7: 3 | B7: Model inventory | C7: ='Gap Assessment'!K7 -> Critical | D7: ='Gap Assessment'!J7 -> 4.69 | E7: No cross-industry inventory obligation. Without one, no other model risk obligation can be evidenced as complete, and APRA cannot assess sector-wide reliance. | F7: Require a complete, current, controlled enterprise inventory including embedded, third-party and recently decommissioned models, with minimum fields specified. | G7: M14 | H7: Policy + Supervision | I7: Open — policy development
A8: 4 | B8: Aggregate model risk and capital | C8: ='Gap Assessment'!K36 -> Critical | D8: ='Gap Assessment'!J36 -> 4.69 | E8: Nothing requires an entity to form a view of model risk in aggregate or to consider it in internal capital assessment, so correlated failure across models sharing data, vendors or assumptions is invisible. | F8: Require aggregate assessment and consideration in internal capital assessment, permitting qualitative measures where quantification is not yet feasible. | G8: M42 | H8: Policy + Capital | I8: Open — policy development
A9: 5 | B9: Model use and misuse | C9: ='Gap Assessment'!K22 -> High | D9: ='Gap Assessment'!J22 -> 4.38 | E9: Misuse is one of the two recognised sources of model risk and is entirely unaddressed outside the capital use test. Nothing requires users to be told a model's limitations. | F9: Require use within approved purpose and conditions, and require limitations to be communicated to users rather than merely recorded. | G9: M27 | H9: Policy | I9: Open — policy development
A10: 6 | B10: Superannuation models | C10: ='Gap Assessment'!K34 -> High | D10: ='Gap Assessment'!J34 -> 4.38 | E10: No comparator authority addresses superannuation model risk, so there is no benchmark. Unit pricing and valuation models determine amounts credited to member accounts and errors transfer value between members irreversibly. | F10: Name the RSE model classes expressly. Scored against the cross-industry benchmark rather than a comparator, because none exists. | G10: M40 | H10: Policy + Superannuation | I10: Open — policy development
A11: 7 | B11: Model risk tiering and proportionality | C11: ='Gap Assessment'!K8 -> High | D11: ='Gap Assessment'!J8 -> 3.75 | E11: Proportionality is a general principle across APRA standards but there is no model risk classification taxonomy, so control intensity is not systematically linked to model risk. | F11: Require a documented tiering methodology using quantitative and qualitative factors that demonstrably drives validation, monitoring and approval intensity, with an express de minimis determination at model level that keeps low-consequence models within identification while relieving them of the full lifecycle. | G11: M04, M05, M15, M16 | H11: Policy | I11: Open — policy development
A12: 8 | B12: Board oversight of model risk | C12: ='Gap Assessment'!K9 -> High | D12: ='Gap Assessment'!J9 -> 3.75 | E12: CPS 220 gives the Board responsibility for the risk management framework, but model risk is not identified as a risk requiring Board attention in its own right and no reporting content is specified. | F12: Require Board approval of the model risk framework and appetite, supported by aggregate, decision-useful reporting rather than model counts. | G12: M06, M13 | H12: Policy | I12: Open — policy development
A13: 9 | B13: MRM framework, policies and capability | C13: ='Gap Assessment'!K11 -> High | D13: ='Gap Assessment'!J11 -> 3.75 | E13: There is no requirement to maintain a model risk management framework as such, no documented model risk policy standard, and no requirement for capability and independence sufficient to validate and challenge models. Model governance obligations sit inside instruments written for other purposes. | F13: Require a documented framework integrated with the risk management framework, policies applied consistently across the entity, and capability and independence sufficient to develop, use, validate, challenge and assure models. | G13: M09, M10, M12 | H13: Policy | I13: Open — policy development
A14: 10 | B14: Pre-implementation testing | C14: ='Gap Assessment'!K16 -> High | D14: ='Gap Assessment'!J16 -> 3.75 | E14: No general bar on using an untested model. Testing expectations exist only within the capital model approval process. | F14: Establish an explicit gate: a model must not be used for a material purpose until tested and residual limitations accepted. | G14: M20 | H14: Policy | I14: Open — policy development
A15: 11 | B15: Independent validation | C15: ='Gap Assessment'!K17 -> High | D15: ='Gap Assessment'!J17 -> 3.75 | E15: Independent validation is required for IRB models under APS 113 and, in a different form, through the Appointed Actuary. There is no general requirement, so a model driving material decisions outside those regimes may never be independently reviewed. | F15: Require independent validation for material models, structured around conceptual soundness, outcomes analysis and ongoing model monitoring, at an intensity set by tier. | G15: M21, M22, M25 | H15: Policy + Supervision | I15: Open — policy development
A16: 12 | B16: Overlays, adjustments and expert judgement | C16: ='Gap Assessment'!K23 -> High | D16: ='Gap Assessment'!J23 -> 3.75 | E16: Post-model adjustments can become the dominant driver of a reported figure without any single approval considering that effect. No Australian instrument governs them generally or requires aggregate reporting. | F16: Require governance of the basis, quantification, approval, duration and removal of overlays, and aggregate reporting of them. | G16: M28 | H16: Policy | I16: Open — policy development
A17: 13 | B17: Implementation controls | C17: ='Gap Assessment'!K20 -> High | D17: ='Gap Assessment'!J20 -> 3.5 | E17: Nothing requires verification that the deployed model reproduces the approved one. This is a recurrent source of failure that methodological validation does not catch. | F17: Require pre-production verification against the approved model and re-verification after material infrastructure or pipeline change. | G17: M25 | H17: Policy + Technology | I17: Open — policy development
A18: 14 | B18: Enterprise-wide scope and retained accountability | C18: ='Gap Assessment'!K6 -> High | D18: ='Gap Assessment'!J6 -> 3.44 | E18: CPS 220 requires a risk management framework covering material risks but does not name model risk, so enterprise-wide coverage depends on each entity's own characterisation. | F18: State enterprise-wide application expressly and confirm that accountability is retained where a model is supplied or operated by another party. | G18: M01 | H18: Policy | I18: Open — policy development
A19: 15 | B19: Ongoing monitoring and drift | C19: ='Gap Assessment'!K24 -> High | D19: ='Gap Assessment'!J24 -> 3.44 | E19: Monitoring expectations are limited to specific model classes. Thresholds are rarely linked to a defined response, so deterioration produces reporting rather than action. | F19: Require monitoring at tier-based frequency with pre-set thresholds linked to investigation, restriction, revalidation or withdrawal. | G19: M29 | H19: Policy + Risk | I19: Open — policy development
A20: 16 | B20: AI and machine learning models | C20: ='Gap Assessment'!K29 -> High | D20: ='Gap Assessment'!J29 -> 3.44 | E20: AI model risk is being addressed through a separate AI workstream, creating a risk that a model built with AI techniques is governed as an AI system but not as a model, or the reverse. | F20: Bring AI models within the model risk framework as a model class, with an explicit boundary rule against the AI risk instrument so nothing falls between. | G20: M34, M35 | H20: Policy | I20: Open — policy development
A21: 17 | B21: Senior accountability for the framework | C21: ='Gap Assessment'!K10 -> High | D21: ='Gap Assessment'!J10 -> 3.13 | E21: No named accountability for model risk as a discipline. Accountability for individual models is implicit in business ownership but framework-level failures have no owner. | F21: Require a named senior executive accountable for the framework, plus a named owner for each model, and settle the interaction with the accountability regime. | G21: M07, M08 | H21: Policy + Legal | I21: Open — policy development
A22: 18 | B22: Development and conceptual soundness | C22: ='Gap Assessment'!K13 -> High | D22: ='Gap Assessment'!J13 -> 3.13 | E22: Development standards exist only for capital models under APS 113 and for actuarial work. Models outside those regimes have no development expectation. | F22: Require documented development standards, conceptual soundness, consideration of alternatives and recording of limitations across all material models. | G22: M17 | H22: Policy | I22: Open — policy development
A23: 19 | B23: Change management and re-approval | C23: ='Gap Assessment'!K21 -> High | D23: ='Gap Assessment'!J21 -> 3.13 | E23: Model change control is prescribed only for capital models. Cumulative change and vendor-initiated change are not addressed anywhere in the framework. | F23: Require materiality assessment of changes individually and cumulatively, and treat provider-initiated change as an entity change event. | G23: M26 | H23: Policy | I23: Open — policy development
A24: 20 | B24: Third-party and vendor models | C24: ='Gap Assessment'!K27 -> High | D24: ='Gap Assessment'!J27 -> 3.13 | E24: CPS 230 governs service providers but not the model risk in a supplied model. Opacity is commonly accepted from vendors at a level that would not be accepted internally. | F24: Apply the full framework to third-party models, require usable information rights without mandating source-code access, and require compensating controls where information is unavailable. | G24: M32, M33 | H24: Policy + Operational Risk | I24: Open — policy development
A25: 21 | B25: Limitations, mitigants and remediation | C25: ='Gap Assessment'!K25 -> High | D25: ='Gap Assessment'!J25 -> 3 | E25: No requirement to record model limitations, apply compensating controls or track remediation to completion. Findings can be closed by explanation without change. | F25: Require recorded limitations, specific compensating controls, tracked remediation and escalation of overdue material findings. | G25: M30 | H25: Policy | I25: Open — policy development
A26: 22 | B26: Data quality, provenance and appropriateness | C26: ='Gap Assessment'!K14 -> Medium | D26: ='Gap Assessment'!J14 -> 2.81 | E26: CPG 235 provides a data governance foundation but is a practice guide, is dated, and does not address model-specific concerns such as proxy data, representativeness or synthetic data. | F26: Require model data to be assessed for appropriateness as well as quality, with lineage to source and documented treatment of proxies and synthetic data. | G26: M18 | H26: Policy + Data | I26: Open — policy development
A27: 23 | B27: Documentation and reproducibility | C27: ='Gap Assessment'!K15 -> Medium | D27: ='Gap Assessment'!J15 -> 2.75 | E27: No cross-industry documentation standard for models. Documentation adequacy is assessed only where a capital or actuarial standard applies. | F27: Adopt the reconstruction test: documentation sufficient for an independent competent person to reproduce material results. | G27: M19 | H27: Policy | I27: Open — policy development
A28: 24 | B28: Approval and conditions of use | C28: ='Gap Assessment'!K19 -> Medium | D28: ='Gap Assessment'!J19 -> 2.5 | E28: Approval requirements exist for capital models only. Elsewhere, models enter use without a recorded approval of version, purpose or conditions. | F28: Require version-specific approval for a defined purpose and conditions, recording limits, thresholds, accepted limitations and review date. | G28: M24 | H28: Policy | I28: Open — policy development
A29: 25 | B29: Independent assurance and internal audit | C29: ='Gap Assessment'!K38 -> Medium | D29: ='Gap Assessment'!J38 -> 2.5 | E29: Internal audit obligations are general. Audit of the model risk framework, and in particular of whether challenge is effective, is not specified and frequently lacks the technical capability to be meaningful. | F29: Require periodic independent assessment of framework design and operating effectiveness, including the effectiveness of validation and challenge. | G29: M44 | H29: Policy + Assurance | I29: Open — policy development
A30: 26 | B30: Valuation and financial reporting models | C30: ='Gap Assessment'!K31 -> Medium | D30: ='Gap Assessment'!J31 -> 2.19 | E30: Valuation model governance and independent price verification are not addressed on a cross-industry basis, despite the output being the reported number itself. | F30: Bring valuation and financial reporting models expressly within scope and require independent price verification as a control distinct from validation. | G30: M37 | H30: Policy | I30: Open — policy development
A31: 27 | B31: Decommissioning and retirement | C31: ='Gap Assessment'!K26 -> Medium | D31: ='Gap Assessment'!J26 -> 2.06 | E31: Retired models whose outputs remain in force — provisions, capital numbers, unit prices, insurance liabilities — are not addressed anywhere. | F31: Require managed decommissioning covering downstream models, outputs still in force, records and data disposition. | G31: M31 | H31: Policy | I31: Open — policy development
A32: 28 | B32: Model risk appetite | C32: ='Gap Assessment'!K12 -> Medium | D32: ='Gap Assessment'!J12 -> 2 | E32: Risk appetite obligations are general. Model risk is rarely expressed in appetite statements in monitorable terms, so it cannot be breached or escalated. | F32: Require an appetite for model risk expressed so that it can be measured, with limits, thresholds and escalation triggers. | G32: M11 | H32: Policy | I32: Open — policy development
A33: 29 | B33: Concentration and substitutability | C33: ='Gap Assessment'!K28 -> Medium | D33: ='Gap Assessment'!J28 -> 2 | E33: Bilateral service provider assessment does not capture correlated reliance on a common external model, data source or platform across the industry. | F33: Require entity-level concentration assessment and support sector-wide monitoring of common model and data dependencies. | G33: M33 | H33: Supervision + Data | I33: Open — policy development
A34: 30 | B34: Stress testing and scenario models | C34: ='Gap Assessment'!K35 -> Medium | D34: ='Gap Assessment'!J35 -> 2 | E34: APRA conducts stress testing but there is no standard governing the models used, whereas the PRA maintains a dedicated supervisory statement on model risk in stress testing. | F34: Bring stress testing, scenario and capital planning models within scope, with explicit treatment of assumption governance and of uncertainty disclosure. | G34: M41 | H34: Policy + Supervision | I34: Open — policy development
A35: 31 | B35: Records and reconstructability | C35: ='Gap Assessment'!K37 -> Medium | D35: ='Gap Assessment'!J37 -> 1.5 | E35: General record-keeping obligations do not specify what must be retained to reconstruct a model's output, approval basis and performance. | F35: Specify reconstructability for material models, with retention aligned to the period over which the decisions informed remain material. | G35: M43 | H35: Policy + Legal | I35: Open — policy development
A36: 32 | B36: Regulatory capital and internal models | C36: ='Gap Assessment'!K30 -> Low | D36: ='Gap Assessment'!J30 -> 1.13 | E36: This is the strongest part of the Australian framework. The residual gap is the absence of a general model risk discipline around the capital model estate, and less developed guidance on model change than the ECB provides. | F36: Preserve the capital standards unchanged and position CPS XXXX to sit alongside them, with the specific capital requirement governing approval, change and conditions of use. | G36: M36 | H36: Policy + Capital | I36: Open — policy development
A37: 33 | B37: Expected credit loss and provisioning models | C37: ='Gap Assessment'!K32 -> Low | D37: ='Gap Assessment'!J32 -> 1.13 | E37: This is a genuine strength. APS 220 transposes BCBS d350 Principle 5 into binding Australian form in near-identical language, requiring ADIs to have sound policies and processes to appropriately validate expected credit loss models, and APG 220 directs ADIs to have regard to the Basel guidance. The residual gap is that the obligation to validate exists without a model risk framework defining what validation consists of, who performs it and what follows a finding — and that APRA's own observations record continuing reliance on sizeable judgement-based adjustments that are not consistently well governed. | F37: Connect the existing APS 220 validation obligation to the model risk framework rather than restating it, govern overlays and scenario assumptions as model risk, and publish the review focus areas so entities know what an APRA-required review under the special purpose engagement provisions of the Audit and Related Matters standards, or under APS 220, would examine. | G37: M38 | H37: Policy + Credit Risk | I37: Open — policy development
A38: 34 | B38: Actuarial and insurance models | C38: ='Gap Assessment'!K33 -> Low | D38: ='Gap Assessment'!J33 -> 0.94 | E38: The Appointed Actuary framework is a genuine strength but was not designed as model risk management. Implementation verification and data quality assessment are not reliably covered. | F38: Require insurers to map which validation elements the actuarial control cycle discharges and which need separate work. | G38: M39 | H38: Policy + Insurance | I38: Open — policy development
A39: 35 | B39: Supervisory engagement and notification | C39: ='Gap Assessment'!K39 -> Low | D39: ='Gap Assessment'!J39 -> 0.75 | E39: Notification architecture is sound but does not identify model failure as a notifiable event, so a material model error may not be reported unless it also constitutes an operational incident. | F39: Cross-reference existing CPS 230 and CPS 234 timeframes rather than create a conflicting deadline, and expect early engagement on material model weakness. | G39: M45 | H39: Policy + Legal | I39: Open — policy development

Sheet Regulatory Crosswalk
A1: Regulatory crosswalk — model risk management
A2: POLICY DEVELOPMENT DRAFT — NOT IN FORCE | Compares substantive content. Legal enforceability differs between authorities and is recorded on the Legal Status Matrix sheet.
A4: Domain | B4: APRA (current) | C4: OCC / Federal Reserve | D4: PRA | E4: OSFI | F4: ECB / SSM | G4: MAS | H4: BCBS | I4: FSB | J4: Proposed CPS XXXX position
A5: Legal character of the framework | B5: Binding prudential standards, but none addresses model risk as such. | C5: Supervisory guidance only, expressly non-enforceable; the sole binding instrument makes guidance non-binding. | D5: Supervisory statement; expectations, not Rulebook rules. | E5: Supervisory guideline; final but not effective until 1 May 2027. | F5: Supervisory guide interpreting binding CRR articles; the CRR is the law, the guide is not. | G5: Binding Notice for capital models; information paper and voluntary principles for AI. | H5: International principles; effect depends on domestic implementation. | I5: Analytical and consultative reports; expressly not standards. | J5: Binding cross-industry prudential standard, deliberately enforceable rather than advisory.
A6: Definition of a model | B6: Not defined on a cross-industry basis. | C6: Narrowed in April 2026 to complex methods applying statistical, economic or financial theories; excludes spreadsheet arithmetic, deterministic rules, and generative and agentic AI. | D6: Principle 1.1(a) sets out a definition firms should adopt as the basis for the scope of their framework, and expects consideration of quantitative methods falling outside it. | E6: Model definition expressly includes AI and machine learning. | F6: Internal models for regulatory capital; machine learning addressed as a technique within them. | G6: Capital models defined in Notice 637; AI models addressed separately. | H6: No general definition; BCBS 239 addresses risk data rather than models. | I6: Uses the OECD AI definition rather than a model definition. | J6: Broad function-based definition capturing deterministic actuarial and pricing calculations, which the US now excludes.
A7: Non-model quantitative tools | B7: Not addressed. | C7: Expressly excluded from the model definition; no control obligation stated in the 2026 guidance. | D7: Principle 1.1 expects firms to consider quantitative methods falling outside the model definition. | E7: Addressed through the risk-based approach. | F7: Not separately addressed. | G7: Not separately addressed. | H7: Not addressed. | I7: Not addressed. | J7: Express requirement to identify material tools outside the definition and control them proportionately.
A8: Enterprise-wide scope | B8: Implicit in CPS 220 but model risk is not named as a material risk. | C8: Applies across the organisation; most relevant above $30bn total assets. | D8: Enterprise-wide, but only for firms with internal model approval. | E8: Enterprise-wide across all models regardless of source or purpose. | F8: Limited to internal models used for regulatory capital. | G8: Capital models; AI practices observed more broadly. | H8: Not applicable. | I8: Not applicable. | J8: Enterprise-wide across all models, all business lines and all APRA-regulated industries.
A9: Proportionality | B9: General principle across all standards; not linked to model risk. | C9: Risk-based; a 2025 bulletin confirms community banks need not validate annually. | D9: Tiering drives control intensity. | E9: Scope, scale and intensity commensurate with model risk (Principle 2.3). | F9: Materiality of the model within the capital framework. | G9: Risk materiality drives control intensity. | H9: Principles applied proportionately. | I9: Explicit proportionality by institution and use-case materiality. | J9: Proportionate by tier, with exceptions documented, time-bound, approved and reviewed.
A10: De minimis and scope relief | B10: No mechanism; model requirements apply only where a capital or actuarial standard reaches them. | C10: Models deemed immaterial may attract only identification and monitoring of the conditions under which their use could become material; the guidance also applies mainly above a $30bn entity threshold. | D10: Tiering determines control intensity; no separate de minimis category. | E10: Principle 2.3 scales scope, scale and intensity to model risk, but Principle 2.1 keeps all models within identification. | F10: Materiality assessment within the internal model framework; no de minimis category. | G10: Risk materiality drives control intensity. | H10: Not addressed. | I10: Proportionality by use-case materiality. | J10: Express de minimis determination at model level, confined to identification, inventory, ownership, classification and reassessment, with prohibited classes, an aggregate test and an anti-disaggregation limb.
A11: Model inventory | B11: No cross-industry obligation. | C11: Described as common industry practice rather than an expectation. | D11: Principle 1.2 requires a model inventory. | E11: Principle 2.1 requires identification and tracking of all models in use or recently decommissioned. | F11: Model register expected for internal models. | G11: Expected for capital models; inventories observed in AI practice. | H11: Not addressed. | I11: Documentation of AI identified as a sound practice. | J11: Complete, current, controlled enterprise inventory including embedded, third-party and recently decommissioned models, with minimum fields prescribed.
A12: Risk tiering | B12: No taxonomy; APS 113 distinguishes only by capital treatment. | C12: Model risk framed as inherent risk in the context of materiality, itself a function of exposure and purpose. | D12: Principle 1.3 model tiering. | E12: Principle 2.2 requires a model risk rating approach assessing key dimensions. | F12: Materiality assessment within the internal model framework. | G12: Risk materiality assessment central to AI control intensity. | H12: Not addressed. | I12: Materiality and risk assessment at inception and thereafter. | J12: Documented tiering on quantitative and qualitative factors, driving validation, monitoring, approval and reporting intensity.
A13: Board and senior accountability | B13: CPS 220 gives the Board the risk management framework; model risk not named. | C13: Roles and responsibilities with defined accountability, including conflicts between development and validation. | D13: Principle 2.1 Board responsibilities and 2.2 SMF accountability for the framework. | E13: Principle 1.1 on reporting structures and resourcing. | F13: Section 5 identification of management body and senior management. | G13: Board and senior management oversight in observed AI practice. | H13: Governance is BCBS 239 Principle 1. | I13: Sound Practices 1 and 2 on strategic direction, oversight, governance and accountability. | J13: Board approves the framework and appetite; a named senior executive is accountable for the framework; every model has a named owner.
A14: Development and conceptual soundness | B14: APS 113 for IRB models only. | C14: Section IV on model development, including purpose statement, user input and testing. | D14: Principle 3.1 model purpose and design; 3.3 development testing. | E14: Principle 3.3 on development processes with clear standards. | F14: Documentation and data governance sections of the overarching principles chapter. | G14: Notice 637 for capital models. | H14: Not addressed directly. | I14: Sound Practice 6 on selection. | J14: Documented development standards, conceptual soundness, consideration of alternatives, and recorded limitations for all material models.
A15: Data | B15: CPG 235 is a non-enforceable guide dating from 2013. | C15: Data quality, relevance and inputs assessed within development testing. | D15: Principle 3.2 the use of data. | E15: Principle 3.2 requires data suitable for the intended use. | F15: Section 3 data governance; separate guide on risk data aggregation and reporting. | G15: Data quality and representativeness prominent in AI practice. | H15: BCBS 239 sets fourteen principles on risk data aggregation and reporting. | I15: Sound Practice 7 on data governance. | J15: Data appropriateness as well as quality, lineage to source, and documented treatment of proxy, external and synthetic data.
... A32: Supervisory notification | B32: CPS 230 and CPS 234 set materiality criteria and timeframes. | C32: No model-specific notification requirement. | D32: Escalation within the framework; no notification rule. | E32: Supervisory engagement expected. | F32: Model change approval required from the supervisor for capital models. | G32: Notification for capital model changes. | H32: Not addressed. | I32: Not addressed. | J32: Cross-references CPS 230 and CPS 234 rather than creating a separate deadline, with early engagement expected on material model weakness.

Sheet Legal Status Matrix
A1: Legal status and scope matrix
A2: POLICY DEVELOPMENT DRAFT — NOT IN FORCE | Do not treat guidance, analytical reports or consultations as binding requirements. An overseas instrument is not binding in Australia in any case.
A4: Source ID | B4: Authority | C4: Instrument | D4: Published | E4: Effective | F4: Legal status | G4: Scope and exclusions | H4: Verification
A5: US-MRM-2026 | B5: OCC / FRB / FDIC | C5: Supervisory Guidance on Model Risk Management — interagency guidance issued as Federal Reserve SR 26-2, OCC Bulletin 2026-13 and FDIC FIL-15-2026 | D5: 17 April 2026 | E5: 17 April 2026 | F5: Interagency supervisory guidance. Expressly non-enforceable: it 'does not set forth enforceable standards or prescriptive requirements' and non-compliance 'will not result in supervisory criticism'. US supervisory guidance does not have the force and effect of law. | G5: Expected to be most relevant to banking organisations with over $30 billion in total assets. Organisations at or below that threshold are generally excluded, though the guidance may still be relevant where model exposure is significant. Generative AI and agentic AI models are expressly outside scope. | H5: Verified — primary source
A6: US-MRM-2011 | B6: OCC / FRB | C6: OCC Bulletin 2011-12 / Federal Reserve SR 11-7 — Supervisory Guidance on Model Risk Management | D6: 4 April 2011 | E6: Rescinded and superseded 17 April 2026 | F6: Superseded supervisory guidance. Rescinded by OCC Bulletin 2026-13 and superseded by Federal Reserve SR 26-2 on 17 April 2026. Was never a regulation. Retained here for provenance because it originated most of the discipline's architecture. | G6: Applied to all banking organisations supervised by the Federal Reserve and the OCC, taking into account size, nature and complexity. Adopted by the FDIC in June 2017 via FIL-22-2017. | H6: Verified — primary source
